Workbook
Name CLV_NWI: [1]Reference!$E$2:$E$7299
Name Counties: [1]Reference!$G$2:$G$14
Name CV_NWI: [1]Reference!$C$3:$C$963
Name Intersections: [1]Reference!$F$2:$F$6708
Name NBI_NWI: [1]Reference!$B$2:$B$1146
Name PK_NWI: [1]Reference!$A$2:$A$427

Sheet About
B2: Information About this File
C3: Version: 1.0
C4: Last Updated: 4/17/2025
B6: PURPOSE
C7: This is a report of collision records from ARIES and other collision data that have been associated through mass geoprocessing to the target pavement key (PK), bridge, large or small culvert, or intersection that is located on INDOT maintained highways. The crash history, crash patterns, and crash pattern analyses have been calculated and tabulated in accordance with Engineering Assessment Manual (EAM), Section 3-3.02(07) and Figure 3-3B for the target INDOT asset.
B11: GENERAL INSTRUCTIONS
C12: • The collision reports and information provided in this workbook are intended to be used only for the safety evaluation of INDOT highways and other assets and shall not be used for any other purpose. • This workbook contains the following information for the "Target Asset" shown on the 'Crash Analysis Report Template' worksheet: o A list of the ARIES collision records related to the target asset is located on the 'Target Collision Records' worksheet; o A list of the ARIES individual (persons involved) records related to the target asset is located on the 'Target Individual Records' worksheet; o A list of the ARIES Master Record Numbers with a summary of asset associations and crash indexing information is located on the 'Data Filtered By Asset' worksheet; and o The crash history, crash patterns, and crash pattern analyses tables for the target asset are located on the 'Crash Analysis Report Template' worksheet. • The engineer performing the crash analysis shall review the collision reports to verify whether or not each of the reports should be included in the analysis. In doing so, the following should be checked: o The engineer should check that the crash severity, manner of collision, pavement condition, lighting condition, and weather condition data entry values shown in the list of collision records and information on the 'Data Filtered By Asset' worksheet accurately reflect the original ARIES collision and individual (persons involved) reports. These values shall be limited to those shown in the EAM, Section Figure 3-3B . o The engineer should check that each of the collisions actually occurred on or near the target asset and that they and are related to the target asset . • Any collision record that the review engineer decides should not be included in the crash analysis may be removed from consideration by deleting the row(s) from the 'Data Filtered By Asset' worksheet. The crash history, crash patterns, and crash pattern analyses tables for the target asset, which are located on the 'Crash Analysis Report Template' worksheet, will recalculate based on the list of records remaining on the 'Data Filtered By Asset' worksheet in accordance with the EAM, Section 3-3.02(07) and Figure 3-3B. • Please note that URL links to the collision diagrams for each of the collision records are included in the 'Data Filtered By Asset' worksheet, which may be useful in determining the manner of collision. • Once the review engineer has verified that the list of collision records are accurate for the target asset, they will then need to perform the required RoadHAT analysis, which will include calculating the ICC and ICF values.
B37: DISCLAIMERS
C38: • The ARIES collision records that are presented in the "Target Collision Records" worksheet shall be reviewed and a RoadHAT analysis shall be prepared by an engineer to complete the required assessment of the crash data for the target INDOT Asset. The crash summary shown in the tables on the Crash Analysis Report Template' worksheet reflect the unevaluated crash reports that have only been roughly associated to the INDOT Asset that was selected for review. • The collision data that is used to calculate and tabulate the crash history, crash patterns, and crash pattern analyses for a selected asset is a result of mass geoprocessing that was performed on every ARIES collision report in 2022 through 2024 to identify and assign nearby INDOT assets that are likely associated to the respective collision report. These assets include pavement keys (PK), bridges, large and small culverts, and intersections that are located on INDOT maintained highways within the INDOT LaPorte District. • In an attempt to assign collisions that were not precisely geolocated by the reporting officer to the associated PK, other text fields on the ARIES reports were evaluated and the radius of the buffer around the INDOT highway roadbed was adjusted accordingly to reflect the strength of indication that the collision actually occurred on or near an INDOT highway. As a result, the engineer evaluating the crash data may find that some of the collision reports that were assigned to an INDOT asset via the mass geoprocessing process may not be related at all to the target INDOT Asset. The engineer that is performing the crash analysis shall screen out these reports accordingly. • Crash Severity, Manner of Collision, Pavement Condition, Lighting Condition, and Weather Condition data entry values in ARIES were changed via mass recategorization to align with the values required by the Engineering Assessment Manual, Section 3-3.02(07) and Figure 3-3B. The engineer shall review each collision record to verify accurate reporting, as the Officer's narrative or other data entry fields, in some cases, contradict one another.
B56: LEGEND
C57: User Entered Value
C58: Auto-Calculated Field
B60: SUPPORT
C61: Please direct questions or requests for assistance to:
C62: Nathan Butts NButts@indot.in.gov
C63: Paul South PSouth@indot.in.gov
B65: DEVELOPED BY
C66: Nathan Butts

Sheet Crash Analysis Report Template
A2: CRASH ANALYSIS REPORT
A4: Example:
A5: =" Crash data was reviewed as part of this assessment and a RoadHAT analysis was prepared. A total of " &F12 &" recorded crashes took place within the project limits during the three-year crash study period (" & B14 & " through " & B15 &"). The following tables summarize the number and types of crashes, as well as the RoadHAT results." -> Crash data was reviewed as part of this assessment and a RoadHAT analysis was prepared. A total of 65 recorded crashes took place within the project limits during the three-year crash study period (2022 through 2024). The following tables summarize the number and types of crashes, as well as the RoadHAT results.
A7: Target Asset:
A8: Asset Type: | B8: Pavement Key
A9: Asset ID: | B9: 40250 | D9: =B9 -> 40250
A11: Crash History:
A12: ICC* | C12: Number of Crashes | F12: =IF($B$9="",0,COUNTA('Data Filtered By Asset'!$A$2:$A$1048576)) -> 65
A13: ICF* | C13: Number of Fatal and Incapacitating Crashes | F13: =IF($B$9="",0,COUNTIF('Data Filtered By Asset'!$D:$D,"Fatal")+COUNTIF('Data Filtered By Asset'!$D:$D,"Incapacitating")) -> 4
A14: First Year of Crash Data | B14: 2022 | C14: Number of Non-Incapacitating Crashes | F14: =IF($B$9="",0,COUNTIF('Data Filtered By Asset'!$D:$D,"Non-incapacitating") + COUNTIF('Data Filtered By Asset'!$D:$D,"Possible") + COUNTIF('Data Filtered By Asset'!$D:$D,"Refused") + COUNTIF('Data Filtered By Asset'!$D:$D,"Unknown")) -> 6
A15: Last Year of Crash Data | B15: 2024 | C15: Number of Property Damage Only Crashes | F15: =IF($B$9="",0,COUNTIF('Data Filtered By Asset'!$D:$D,"No Injury") + COUNTIF('Data Filtered By Asset'!$D:$D,"Not Reported") + COUNTIF('Data Filtered By Asset'!$D:$D,"PDO")) -> 55
A16: *To be determined by the Engineer using RoadHAT.
A18: Crash Patterns: Manner of Collision
A19: Manner of Collision | C19: Number | D19: Percent
A20: Backing Crash | C20: =IF($B$9="",0,E20&" ("&F20&")") -> 5 (0) | D20: =IF(E20=0,0,E20/$E$30) -> 0.076923077 | E20: =IF($B$9="",0,COUNTIF('Data Filtered By Asset'!$L$2:$L$1048576,"Backing Crash")) -> 5 | F20: =COUNTIFS('Data Filtered By Asset'!$L$2:$L$1048576,"Backing Crash", 'Data Filtered By Asset'!$D$2:$D$1048576,"<>No Injury", 'Data Filtered By Asset'!$D$2:$D$1048576,"<>Not Reported", 'Data Filtered By Asset'!$D$2:$D$1048576,"<>PDO") -> 0
A21: Collision With Animal (Including Deer) * | C21: =IF($B$9="",0,E21&" ("&F21&")") -> 26 (1) | D21: =IF(E21=0,0,E21/$E$30) -> 0.4 | E21: =IF($B$9="",0,COUNTIF('Data Filtered By Asset'!$L$2:$L$1048576,"Collision With Animal (Including Deer)")) -> 26 | F21: =COUNTIFS('Data Filtered By Asset'!$L$2:$L$1048576,"Collision With Animal (Including Deer)", 'Data Filtered By Asset'!$D$2:$D$1048576,"<>No Injury", 'Data Filtered By Asset'!$D$2:$D$1048576,"<>Not Reported", 'Data Filtered By Asset'!$D$2:$D$1048576,"<>PDO") -> 1
A22: Collision With Object in Road | C22: =IF($B$9="",0,E22&" ("&F22&")") -> 1 (1) | D22: =IF(E22=0,0,E22/$E$30) -> 0.015384615 | E22: =IF($B$9="",0,COUNTIF('Data Filtered By Asset'!$L$2:$L$1048576,"Collision With Object in Road")) -> 1 | F22: =COUNTIFS('Data Filtered By Asset'!$L$2:$L$1048576,"Collision With Object in Road", 'Data Filtered By Asset'!$D$2:$D$1048576,"<>No Injury", 'Data Filtered By Asset'!$D$2:$D$1048576,"<>Not Reported", 'Data Filtered By Asset'!$D$2:$D$1048576,"<>PDO") -> 1
A23: Head On (Between Motor Vehicles) | C23: =IF($B$9="",0,E23&" ("&F23&")") -> 0 (0) | D23: =IF(E23=0,0,E23/$E$30) -> 0 | E23: =IF($B$9="",0,COUNTIF('Data Filtered By Asset'!$L$2:$L$1048576,"Head On (Between Motor Vehicles)")) -> 0 | F23: =COUNTIFS('Data Filtered By Asset'!$L$2:$L$1048576,"Head On (Between Motor Vehicles)", 'Data Filtered By Asset'!$D$2:$D$1048576,"<>No Injury", 'Data Filtered By Asset'!$D$2:$D$1048576,"<>Not Reported", 'Data Filtered By Asset'!$D$2:$D$1048576,"<>PDO") -> 0
A24: Left Turn, Right Turn or Angle | C24: =IF($B$9="",0,E24&" ("&F24&")") -> 5 (0) | D24: =IF(E24=0,0,E24/$E$30) -> 0.076923077 | E24: =IF($B$9="",0,COUNTIF('Data Filtered By Asset'!$L$2:$L$1048576,"Left Turn, Right Turn or Angle")) -> 5 | F24: =COUNTIFS('Data Filtered By Asset'!$L$2:$L$1048576,"Left Turn, Right Turn or Angle", 'Data Filtered By Asset'!$D$2:$D$1048576,"<>No Injury", 'Data Filtered By Asset'!$D$2:$D$1048576,"<>Not Reported", 'Data Filtered By Asset'!$D$2:$D$1048576,"<>PDO") -> 0
A25: Opposite Direction Sideswipe | C25: =IF($B$9="",0,E25&" ("&F25&")") -> 3 (1) | D25: =IF(E25=0,0,E25/$E$30) -> 0.046153846 | E25: =IF($B$9="",0,COUNTIF('Data Filtered By Asset'!$L$2:$L$1048576,"Opposite Direction Sideswipe")) -> 3 | F25: =COUNTIFS('Data Filtered By Asset'!$L$2:$L$1048576,"Opposite Direction Sideswipe", 'Data Filtered By Asset'!$D$2:$D$1048576,"<>No Injury", 'Data Filtered By Asset'!$D$2:$D$1048576,"<>Not Reported", 'Data Filtered By Asset'!$D$2:$D$1048576,"<>PDO") -> 1
A26: Ran Off Road | C26: =IF($B$9="",0,E26&" ("&F26&")") -> 14 (4) | D26: =IF(E26=0,0,E26/$E$30) -> 0.21538462 | E26: =IF($B$9="",0,COUNTIF('Data Filtered By Asset'!$L$2:$L$1048576,"Ran Off Road")) -> 14 | F26: =COUNTIFS('Data Filtered By Asset'!$L$2:$L$1048576,"Ran Off Road", 'Data Filtered By Asset'!$D$2:$D$1048576,"<>No Injury", 'Data Filtered By Asset'!$D$2:$D$1048576,"<>Not Reported", 'Data Filtered By Asset'!$D$2:$D$1048576,"<>PDO") -> 4
A27: Rear End | C27: =IF($B$9="",0,E27&" ("&F27&")") -> 5 (1) | D27: =IF(E27=0,0,E27/$E$30) -> 0.076923077 | E27: =IF($B$9="",0,COUNTIF('Data Filtered By Asset'!$L$2:$L$1048576,"Rear End")) -> 5 | F27: =COUNTIFS('Data Filtered By Asset'!$L$2:$L$1048576,"Rear End", 'Data Filtered By Asset'!$D$2:$D$1048576,"<>No Injury", 'Data Filtered By Asset'!$D$2:$D$1048576,"<>Not Reported", 'Data Filtered By Asset'!$D$2:$D$1048576,"<>PDO") -> 1
A28: Same Direction Sideswipe | C28: =IF($B$9="",0,E28&" ("&F28&")") -> 4 (1) | D28: =IF(E28=0,0,E28/$E$30) -> 0.061538462 | E28: =IF($B$9="",0,COUNTIF('Data Filtered By Asset'!$L$2:$L$1048576,"Same Direction Sideswipe")) -> 4 | F28: =COUNTIFS('Data Filtered By Asset'!$L$2:$L$1048576,"Same Direction Sideswipe", 'Data Filtered By Asset'!$D$2:$D$1048576,"<>No Injury", 'Data Filtered By Asset'!$D$2:$D$1048576,"<>Not Reported", 'Data Filtered By Asset'!$D$2:$D$1048576,"<>PDO") -> 1
A29: Other | C29: =IF($B$9="",0,E29&" ("&F29&")") -> 2 (1) | D29: =IF(E29=0,0,E29/$E$30) -> 0.030769231 | E29: =IF($B$9="",0,COUNTIF('Data Filtered By Asset'!$L$2:$L$1048576,"Other")) -> 2 | F29: =COUNTIFS('Data Filtered By Asset'!$L$2:$L$1048576,"Other", 'Data Filtered By Asset'!$D$2:$D$1048576,"<>No Injury", 'Data Filtered By Asset'!$D$2:$D$1048576,"<>Not Reported", 'Data Filtered By Asset'!$D$2:$D$1048576,"<>PDO") -> 1
A30: Total | C30: =SUM(E20:E29)&" ("&SUM(F20:F29)&")" -> 65 (10) | D30: =SUM(D20:D29) -> 1 | E30: =IF($B$9="",0,COUNTA('Data Filtered By Asset'!$A$2:$A$1048576)) -> 65
A31: X (Y): X indicates the number of crash type Y indicates those resulting in injury
A32: *In almost all cases, deer crashes and other animal crashes should be removed from the analysis completely prior to completing the RoadHAT report.
A34: The top two tables shall be included in the Crash Analysis section of the scope document (AbbEngRpt or EngRpt). Include a summary analysis of the analysis as well as recommendations based on the analysis’ findings.
A36: Example:
A37: The RoadHAT analysis resulted in an Index of Crash Frequency (ICF) of 1.26 and an Index of Crash Cost (ICC) of 3.13. This analysis indicates that this road section is not performing as expected and that the number of crashes significantly exceeds the expected number of crashes for this type of roadway. The high value of the ICC indicates that the crash severity is higher than should be expected for this type of roadway. Based on the existing crash patterns, this report will focus alternative development to integrate crash mitigation treatments that will facilitate reduction of the rear end, right angle, and sideswipe crash types. The following crash mitigation treatments were reviewed to improve the overall safety of the corridor: • Install a Two‐way Left Turn Lane (TWLTL) • Pave deteriorated shoulder (8ft) • Install centerline rumble strips • Install edge line rumble strips
A40: Crash Pattern Analysis:
A42: Pavement Condition Percentages
A43: Type | B43: Number | C43: Percent** | D43: Standard Value* Comparison:
A44: On Snowy or Icy Pavement | B44: =IF($B$9="",0,COUNTIFS('Data Filtered By Asset'!$R$2:$R$1048576,"On Snowy or Icy Pavement",'Data Filtered By Asset'!$L$2:$L$1048576,"<>Collision With Animal (Including Deer)")) -> 5 | C44: =IF(B44=0,0,B44/$B$48) -> 0.12820513 | D44: 0.1118
A45: On Wet Pavement | B45: =IF($B$9="",0,COUNTIFS('Data Filtered By Asset'!$R$2:$R$1048576,"On Wet Pavement",'Data Filtered By Asset'!$L$2:$L$1048576,"<>Collision With Animal (Including Deer)")) -> 2 | C45: =IF(B45=0,0,B45/$B$48) -> 0.051282051 | D45: 0.1549
A46: On Dry Pavement | B46: =IF($B$9="",0,COUNTIFS('Data Filtered By Asset'!$R$2:$R$1048576,"On Dry Pavement",'Data Filtered By Asset'!$L$2:$L$1048576,"<>Collision With Animal (Including Deer)")) -> 32 | C46: =IF(B46=0,0,B46/$B$48) -> 0.82051282 | D46: 0.7317
A47: On Other Condition Pavement | B47: =IF($B$9="",0,COUNTIFS('Data Filtered By Asset'!$R$2:$R$1048576,"On Other Condition Pavement",'Data Filtered By Asset'!$L$2:$L$1048576,"<>Collision With Animal (Including Deer)")) -> 0 | C47: =IF(B47=0,0,B47/$B$48) -> 0 | D47: 0.00163
A48: Total | B48: =IF($B$9="",0,COUNTIFS('Data Filtered By Asset'!$A$2:$A$1048576,">0",'Data Filtered By Asset'!$L$2:$L$1048576,"<>Collision With Animal (Including Deer)")) -> 39 | C48: =SUM(C44:C47) -> 1
A49: *Standard values are based on 2014-2018 data for all state-owned facilities. Standard values are included for comparison purposes only.
A50: **Calculated percentages exclude all collisions with animals.
...

Sheet Target Collision Records
A1: Master_Record_Number | B1: County | C1: Township | D1: City | E1: Collision Date | F1: Collision Time | G1: Vehicles Involved | H1: Trailers Involved | I1: Number Injured | J1: Number Dead | K1: Number Deer | L1: House Number | M1: Roadway Name | N1: Roadway Suffix | O1: Roadway Number | P1: Roadway Interchange | Q1: Roadway Ramp | R1: Roadway Id | S1: Intersecting Road | T1: Intersecting Road Number | U1: Mile Marker | V1: Interchange | W1: Corporate Limits? | X1: Property Type | Y1: Feet From | Z1: Direction | AA1: Latitude | AB1: Longitude | AC1: Roadway Class | AD1: Traffic Control Devices? | AE1: Locality | AF1: School Zone? | AG1: Rumble Strips? | AH1: Construction? | AI1: Construction Type | AJ1: Light Condition | AK1: Weather Conditions | AL1: Surface Condition | AM1: Type of Median | AN1: Roadway Junction Type | AO1: Road Character | AP1: Roadway Surface | AQ1: Primary Factor | AR1: Damage Estimate | AS1: Manner of Collision | AT1: Investigation Complete? | AU1: Photos Taken? | AV1: Unique Location Id | AW1: State Property Damage? | AX1: Traffic Control | AY1: NARRATIVE
A2: 903960115 | B2: FULTON | C2: ROCHESTER | D2: ROCHESTER | E2: 44575 | F2: 0.30555556 | G2: 1 | I2: 0 | J2: 0 | K2: 1 | M2: E STATE RD 14 | R2: E STATE RD 14 | W2: N | Y2: 0 | AA2: 41.054296 | AB2: -86.131993 | AE2: RURAL | AF2: N | AG2: N | AH2: N | AJ2: DARK (NOT LIGHTED) | AK2: CLOUDY | AL2: DRY | AN2: NO JUNCTION INVOLVED | AP2: ASPHALT | AQ2: ANIMAL/OBJECT IN ROADWAY | AR2: $5001 TO $10000 | AS2: RIGHT ANGLE | AT2: Y | AU2: N | AV2: ESTATERD14 | AW2: 0 | AY2: On Friday, January 14, 2022 at 07:20, shriver, don responded to a crash on E State Rd 14. At the time of the crash, the weather was Cloudy and the road surface was Dry.Vehicle 1, Tan Jeep Grand, Going straight. {Driver Statements} {Witness Statements} {Conclusion} Vehicle one was traveling West on SR 14 near CR 575 E when a deer entered the roadway and was struck.
A3: 903960099 | B3: FULTON | C3: HENRY | D3: AKRON | E3: 44578 | F3: 0.24166667 | G3: 1 | I3: 0 | J3: 0 | K3: 1 | M3: STATE RD 14 | R3: STATE RD 14 | S3: S 900 E | W3: N | Y3: 574 | AA3: 41.039318 | AB3: -86.078613 | AC3: STATE ROAD | AE3: RURAL | AF3: N | AG3: N | AH3: N | AJ3: DARK (NOT LIGHTED) | AK3: CLOUDY | AL3: DRY | AN3: NO JUNCTION INVOLVED | AP3: ASPHALT | AQ3: ANIMAL/OBJECT IN ROADWAY | AR3: $5001 TO $10000 | AS3: COLLISION WITH DEER | AT3: N | AU3: N | AV3: STATERD14S900E | AW3: 0 | AY3: D1 was eastbound on state road 14 near county road 900 E when a deer entered the roadway. D1 was unable to avoid striking the deer.
A4: 903980173 | B4: FULTON | C4: ROCHESTER | D4: ROCHESTER | E4: 44594 | F4: 0.43055556 | G4: 1 | I4: 0 | J4: 0 | K4: 0 | M4: E STATE RD 14 | R4: E STATE RD 14 | W4: N | Y4: 0 | AA4: 41.054375 | AB4: -86.144637 | AC4: STATE ROAD | AE4: RURAL | AF4: N | AG4: N | AH4: N | AJ4: DAYLIGHT | AK4: SNOW | AL4: SNOW/SLUSH | AN4: NO JUNCTION INVOLVED | AP4: ASPHALT | AQ4: SPEED TOO FAST FOR WEATHER CONDITIONS | AR4: $5001 TO $10000 | AS4: RAN OFF ROAD | AT4: Y | AU4: Y | AV4: ESTATERD14 | AW4: 0 | AY4: On Wednesday, February 2, 2022 at 10:20, Wilburn, Scott responded to a crash on E State Rd 14. At the time of the crash, the weather was Snow and the road surface was Snow/Slush.Vehicle 1, Red Chevrolet Malibu, Going straight. DRIVER ADVISED SHE SLID ON THE ROADWAY AND WENT OFF THE ROAD STRIKING THE UTILITY POLE.STRIKING THE POLE CAUSED EXTENSIVE DAMAGE TO THE PASSENGER SIDE OF THE VEHICLE. DRIVER AND FATHER WHO ARRIVED CONTACTED ROADSIDE ASSISTANCE TO COME AND TOW THE VEHICLE.
A5: 904016240 | B5: FULTON | C5: HENRY | D5: AKRON | E5: 44653 | F5: 0.52986111 | G5: 1 | I5: 0 | J5: 0 | K5: 1 | M5: STATE RD 14 & 700 E | R5: STATE RD 14 & 700 E | W5: N | Y5: 0 | AA5: 41.050372 | AB5: -86.112287 | AE5: RURAL | AF5: N | AG5: N | AH5: N | AJ5: DARK (LIGHTED) | AK5: CLEAR | AL5: DRY | AN5: NO JUNCTION INVOLVED | AP5: ASPHALT | AQ5: ANIMAL/OBJECT IN ROADWAY | AR5: $5001 TO $10000 | AS5: COLLISION WITH DEER | AT5: Y | AU5: N | AV5: STATERD14&700E | AW5: 0 | AY5: On Saturday, April 2, 2022 at 12:43, Salientes, Jeryl responded to a crash on State Rd 14 & 700 E. At the time of the crash, the weather was Clear and the road surface was Dry.Vehicle 1, Gray Nissan Altima, Going straight, westbound on SR 14. Deer was in roadway and vehicle 1 hit deer with the front side of the vehicle.
A6: 904030727 | B6: FULTON | C6: HENRY | D6: ATHENS | E6: 44674 | F6: 0.85416667 | G6: 2 | I6: 0 | J6: 0 | K6: 0 | M6: E STATE RD 14 | R6: E STATE RD 14 | S6: S 650 E | W6: N | Y6: 581 | AA6: 41.054264 | AB6: -86.123984 | AC6: PRIVATE DRIVE | AE6: RURAL | AF6: N | AG6: N | AH6: N | AJ6: DARK (LIGHTED) | AK6: CLEAR | AL6: DRY | AN6: NO JUNCTION INVOLVED | AP6: GRAVEL | AQ6: UNSAFE BACKING | AR6: $5001 TO $10000 | AS6: BACKING CRASH | AT6: Y | AU6: N | AV6: S650EESTATERD14 | AW6: 0 | AY6: On Saturday, April 23, 2022 at 20:30, KROFT, CLARK responded to a crash on E State Rd 14 581 ft at intersection of S 650 E. At the time of the crash, the weather was Clear and the road surface was Dry.Vehicle 1, Black Chevrolet Equinox, Backing. Vehicle 2, Black Chevrolet Camaro, Parked (unattended). {Driver Statements} DRIVER 1 STATED SHE WAS BACKING VEHICLE 1 IN THE DRIVEWAY AND DIDNT SEE VEHICLE 2. RIGHT REAR OF VEHICLE 1 STRUCK DRIVERS SIDE OF VEHICLE 2. VEHICLE 2 WAS UNATTENDED. {Witness Statements} {Conclusion}
A7: 904024718 | B7: FULTON | C7: HENRY | D7: ROCHESTER | E7: 44675 | F7: 0.50694444 | G7: 2 | I7: 0 | J7: 0 | K7: 0 | M7: STATE RD 14 | R7: STATE RD 14 | W7: N | Y7: 0 | AA7: 41.039082 | AB7: -86.035796 | AC7: STATE ROAD | AE7: URBAN | AF7: N | AG7: N | AH7: N | AJ7: DAYLIGHT | AK7: CLEAR | AL7: DRY | AN7: NO JUNCTION INVOLVED | AP7: ASPHALT | AQ7: FAILURE TO YIELD RIGHT OF WAY | AR7: $5001 TO $10000 | AS7: REAR END | AT7: Y | AU7: Y | AV7: STATERD14 | AW7: 0 | AY7: On Sunday, April 24, 2022 at 12:10, shriver, don responded to a crash on State Rd 14. At the time of the crash, the weather was Clear and the road surface was Dry.Vehicle 1, Silver\Aluminum Bmw X5, Overtaking/Passing. Vehicle 2, Gray Chevrolet Equinox, Turning left. {Driver Statements} D-2 advised he was turning left into the driveway at 11088 E SR 14 and was struck by V-1 which was trying to pass V-2.D-1 advised he did not see the turn signal if it was on and attempted to pass not realizing that V-2 was beginning to turn left.{Witness Statements} {Conclusion} V-2 was turning left and D-1 did not realize it. D-1 began to pass V-2 and struck V-2.
A8: 904051798 | B8: FULTON | C8: HENRY | D8: ATHENS | E8: 44721 | F8: 0.97222222 | G8: 1 | I8: 1 | J8: 0 | K8: 0 | M8: STATE RD 14 | R8: STATE RD 14 | W8: N | Y8: 0 | AA8: 41.049178 | AB8: -86.110438 | AC8: STATE ROAD | AE8: RURAL | AF8: N | AG8: N | AH8: N | AJ8: DARK (NOT LIGHTED) | AK8: CLEAR | AL8: DRY | AN8: NO JUNCTION INVOLVED | AP8: ASPHALT | AQ8: ANIMAL/OBJECT IN ROADWAY | AR8: $5001 TO $10000 | AS8: COLLISION WITH DEER | AT8: Y | AU8: Y | AV8: STATERD14 | AW8: 0 | AY8: V1 was traveling East bound on St Rd. 14 just past Cr 700 E. enroute to a medical emergency. D1 stated shortly after passing 700 E. a deer entered the roadway and he was unable to keep from striking the deer. V1 sustained damage to the front of the vehicle. D1 was transported to woodlawn hospital by Deputy Miller for complaint of head pain.
A9: 904090957 | B9: FULTON | C9: HENRY | D9: AKRON | E9: 44781 | F9: 0.83333333 | G9: 1 | I9: 0 | J9: 0 | K9: 0 | M9: STATE RD 14 | R9: STATE RD 14 | S9: S 975 E | W9: N | Y9: 0 | AA9: 41.038709 | AB9: -86.059707 | AC9: STATE ROAD | AE9: RURAL | AF9: N | AG9: N | AH9: N | AJ9: DAYLIGHT | AK9: RAIN | AL9: WET | AN9: NO JUNCTION INVOLVED | AP9: ASPHALT | AQ9: OVERCORRECTING/OVERSTEERING | AR9: $5001 TO $10000 | AS9: RAN OFF ROAD | AT9: Y | AU9: N | AV9: STATERD14S975E | AW9: 0 | AY9: V1 WAS TRAVELING WEST ON SR 14. THE DRIVER STATED SHE BEGAN TO HYDROPLAIN DUE TO RAIN WATER ON THE ROADWAY. SHE STATED THAT THE VEHICLE SPUN AROUND AND SHE RAN OFF THE ROADWAY. V1 WENT DOWN AN EMBANKMENT AND THEN THROUGH A FENCE. V1 WAS MOVED PRIOR TO MY ARRIVAL BUT I WAS TOLD THAT IT CAME TO REST ON THE SOUTH SIDE OF THE FENCE. IT WAS DRIVEN TO THE TOP OF A HILL BEFORE THEY CALLED FOR A POLICE REPORT.
A10: 904098101 | B10: FULTON | C10: HENRY | D10: ATHENS | E10: 44783 | F10: 0.62083333 | G10: 2 | I10: 0 | J10: 0 | K10: 0 | M10: E STATE RD 14 | R10: E STATE RD 14 | S10: S 650 E | W10: N | Y10: 0 | AA10: 41.054298 | AB10: -86.124417 | AC10: STATE ROAD | AE10: RURAL | AF10: N | AG10: N | AH10: N | AJ10: DAYLIGHT | AK10: CLEAR | AL10: DRY | AN10: NO JUNCTION INVOLVED | AP10: ASPHALT | AQ10: FAILURE TO YIELD RIGHT OF WAY | AR10: $5001 TO $10000 | AS10: LEFT TURN | AT10: Y | AU10: Y | AV10: S650EESTATERD14 | AW10: 0 | AY10: On Wednesday, August 10, 2022 at 14:54, Miller, Abbi responded to a crash on E State Rd 14 at intersection of S 650 E. At the time of the crash, the weather was Clear and the road surface was Dry.Vehicle 1, Black Chevrolet Silverado, Maintaining path of travel. Vehicle 2, Black Chevrolet Traverse, Maintaining path of travel. V1 was traveling west on SR 14 and V2 was traveling east on SR 14. D1 was turning north into the parking lot of a business when he did not see V2 and hit the front end of V2.
A11: 904118112 | B11: FULTON | C11: ROCHESTER | D11: ROCHESTER | E11: 44826 | F11: 0.44791667 | G11: 1 | I11: 1 | J11: 0 | K11: 0 | M11: E STATE RD 14 | R11: E STATE RD 14 | S11: OAKHILL LANE | W11: N | Y11: 0 | AA11: 41.054816 | AB11: -86.156326 | AC11: STATE ROAD | AE11: RURAL | AF11: N | AG11: N | AH11: N | AJ11: DAYLIGHT | AK11: CLOUDY | AL11: DRY | AN11: NO JUNCTION INVOLVED | AP11: ASPHALT | AQ11: FAILURE TO MAINTAIN LANE | AR11: $10001 TO $25000 | AS11: RAN OFF ROAD | AT11: Y | AU11: Y | AV11: OAKHILLLANEESTATERD14 | AW11: 0 | AY11: V1 was westbound on state road 14 near Oakhill LN when V1 crossed the center line and went off the roadway on the south side of the road. V1 struck a horse trailer that was parked on the property. V1 ended up on it's roof after striking the horse trailer. Witness 1 stated that he looked in his rearview mirror and saw V1 swerving in the westbound lane before the vehicle crossed the center line and went off the roadway. W2 was eastbound when V1 crossed the center line just in front of W2. W2 stated that V1 was swerving in the westbound lane before crossing in front of him and the V1 struck the parked horse trailer. There was damage to the passenger side rear of the horse trailer where V1 struck it.
A12: 904135408 | B12: FULTON | C12: HENRY | D12: AKRON | E12: 44847 | F12: 0.62222222 | G12: 2 | I12: 0 | J12: 0 | K12: 0 | M12: W ROCHESTER ST | R12: W ROCHESTER ST | S12: W ROCHESTER ST | W12: Y | Y12: 0 | AA12: 41.038827 | AB12: -86.028343 | AC12: LOCAL/CITY ROAD | AE12: URBAN | AF12: N | AG12: N | AH12: N | AJ12: DAYLIGHT | AK12: CLOUDY | AL12: DRY | AN12: FOUR-WAY INTERSECTION | AP12: ASPHALT | AQ12: OTHER (VEHICLE) - EXPLAIN IN NARRATIVE | AR12: $2501 TO $5000 | AS12: REAR END | AT12: N | AU12: N | AV12: WROCHESTERSTWROCHESTERST | AW12: 0 | AY12: V1 WAS TRAVELING EAST ON ROCHESTER ST. V1 CAME TO A STOP AT THE INTERSECTION OF ROCHESTER ST AND MISHAWAKA ST. V1 WAS THEN REAR ENDED BY V2. V1 THEN TURNED SOUTH ONTO MISHAWAKA ST AND CAME TO A STOP IN A PARKING SPOT TO GET OUT OF TRAFFIC FOR SAFETY.V2 WAS TRAVELING EAST ON ROCHESTER ST. AS V1 STOPPED AT THE INTERSECTION, V2 REAR ENDED V1. V2 THEN TURNED NORTH ONTO MISHAWAKA ST AND CONTINUED NORTH LEAVING THE SCENE OF THE ACCIDENT. I WAS UNABLE TO LOCATE V2.
A13: 904137984 | B13: FULTON | C13: HENRY | D13: ATHENS | E13: 44854 | F13: 0.37013889 | G13: 2 | I13: 0 | J13: 0 | K13: 0 | M13: STATE RD 14 | R13: STATE RD 14 | S13: 650 E | W13: Y | Y13: 300 | AA13: 41.054313 | AB13: -86.125155 | AC13: STATE ROAD | AE13: URBAN | AF13: N | AG13: N | AH13: N | AJ13: DAYLIGHT | AK13: CLEAR | AL13: DRY | AN13: NO JUNCTION INVOLVED | AP13: ASPHALT | AQ13: IMPROPER PASSING | AR13: $5001 TO $10000 | AS13: RIGHT ANGLE | AT13: Y | AU13: Y | AV13: STATERD14650E | AW13: 0 | AY13: V1 was traveling west on SR 14 approaching Athens, IN. V-1 began to pass V2 in a No Passing Zone. As V1 entered back into the west bound lane, V1's rear bumber collided with the front bumper of V2. V1 left the roadway and collided with a trash container owned by Republic Services.D2 advised, D1 passed him in a No Passing Zone and cut in front of him.W1 who was east bound stated V1 was passing in the No Passing Zone.October 27th, 2022 I was advised by Matt Clevenger, Clevenger Engineering, when V1 collided with the trash container, the trash container was shoved into the air conditioner casusing substantial damage.REPUBLIC SERVICES 15469S SR17 CULVER,IN 46511CLEVENGER ENGINEERING 6310E SR14 ROCHESTER,IN 46975
A14: 904143902 | B14: FULTON | C14: HENRY | D14: AKRON | E14: 44860 | F14: 0.56805556 | G14: 1 | I14: 0 | J14: 0 | K14: 1 | M14: STATE RD 14 | R14: STATE RD 14 | S14: S 975 E | W14: N | Y14: 422 | AA14: 41.038587 | AB14: -86.060811 | AC14: STATE ROAD | AE14: RURAL | AF14: N | AG14: N | AH14: N | AJ14: DARK (NOT LIGHTED) | AK14: CLEAR | AL14: DRY | AN14: NO JUNCTION INVOLVED | AP14: ASPHALT | AQ14: ANIMAL/OBJECT IN ROADWAY | AR14: $2501 TO $5000 | AS14: COLLISION WITH DEER | AT14: Y | AU14: Y | AV14: STATERD14S975E | AW14: 0 | AY14: On Wednesday, October 26, 2022 at 13:38, Haney, Ryan responded to a crash on State Rd 14 422 ft at intersection of S 975 E. At the time of the crash, the weather was Clear and the road surface was Dry.V1 was traveling west on SR 14 approaching 975 E when a deer entered the roadway. V1 was unable to avoid striking the deer. V1 sustained damage to the entire front end and surrounding panels.
A15: 904150285 | B15: FULTON | C15: HENRY | D15: AKRON | E15: 44868 | F15: 0.7125 | G15: 1 | I15: 1 | J15: 0 | K15: 0 | O15: 14 | R15: 14 | U15: 925 | W15: N | Y15: 0 | AA15: 41.038355 | AB15: -86.071482 | AC15: STATE ROAD | AE15: RURAL | AF15: N | AG15: N | AH15: N | AJ15: DAYLIGHT | AK15: CLEAR | AL15: DRY | AN15: NO JUNCTION INVOLVED | AP15: ASPHALT | AQ15: FAILURE TO MAINTAIN LANE | AR15: $10001 TO $25000 | AS15: RAN OFF ROAD | AT15: Y | AU15: Y | AV15: 14 | AW15: 0 | AY15: On November 3, 2022, I resopnded to a single vehicle crash at the intersection of State Road 14 and County Road 925 East. When I arrived on scene, I observed Driver 1 outside of the vehicle with injuries to his face (mainly nose). Driver 1 refused an ambulance multiple times and stated he would go to the hospital on his own. Driver 1 stated he was driving West on State Road 14 when a eastbound red in color Ford Ranger was attempting to pass another eastbound vehicle. Driver 1 stated he went slightly off of the northside of the roadway to avoid striking the Ford Ranger head on. Driver 1 stated as he was going off of the roadway, he was unable to reenter the roadway as the hill/ditch "sucked him in". Driver 1 stated he has insurance however does not have it with him. Driver 1 left with a friend who transported him to Woodlawn Hospital in Rochester. I was later put in contact with the vehicle owner who advised Driver 1 did not have permission to drive the vehicle as it does not have any active insurance on it. The owner of the vehicle did not want to pursue any criminal charges at this time. After checking with dispatch, it was discovered that Driver 1 has had previous conviction(s) for insurance violations. I went to Woodlawn hospital and issued Driver 1 an Information and Summons for operating without financial responsibility with prior conviction. Vehicle 1 was originally to be towed by a local company per the owner's reqeust, however the tow company stated they would be unable to retreive the vehicle. Dispatch contacted the next available tow service which ended up being Hammel's Wrecker Service out of Rochester. Deputy Ryan UtterFulton County Sheriff's Office
A16: 904157284 | B16: FULTON | C16: ROCHESTER | D16: ATHENS | E16: 44872 | F16: 0.65694444 | G16: 1 | I16: 0 | J16: 0 | K16: 0 | M16: 6379 E STATE RD 14 | R16: 6379 E STATE RD 14 | U16: 650 | W16: N | Y16: 0 | AA16: 41.054217 | AB16: -86.123301 | AC16: STATE ROAD | AE16: RURAL | AF16: N | AG16: N | AH16: N | AJ16: DAYLIGHT | AK16: CLEAR | AL16: DRY | AN16: NO JUNCTION INVOLVED | AP16: ASPHALT | AQ16: OVERSIZE/OVERWEIGHT LOAD | AR16: $1001 TO $2500 | AS16: OTHER - EXPLAIN IN NARRATIVE | AT16: Y | AU16: Y | AV16: 6379ESTATERD14 | AW16: 0 | AY16: On November 7, 2022, Deputy Matthew Craig and myself responded to a report of lines down across State Road 14 near the address of 6379 East State Road 14. As I was blocking the roadway at State Road 14 and County Road 700 East, a witness approched me and stated he observed a semi (Vehicle 1) hauling a combine on a flat bed come in contact with the utility line across the roadway. The witness was driving Eastbound and Vehicle 1 was driving Westbound. The witness stated Vehicle 1 did not stop. While I was enroute to this location I passed a New Holland semi hauling farm equipment. I had my dispatch contact New Holland of Rochester who was able to put me in contact with Driver 1. Driver 1 stated he did not know that he had struck anything. Driver 1 stated the height of the combine on the trailer was exactly 14 foot. Driver 1 believes if there was a line struck that the line was possibly not hung at the required height. Driver 1 also stated he does not believe there to be damage to Vehicle 1, the trailer, or the combine he was hauling. Driver 1 provided me with the required information for this report via pictures sent to my department cell phone. I am not taking any law enforcment action for this crash other than this crash report. Photographs of the scene taken by Deputy Craig, and the photos I received from Driver 1 will be stored on the Fulton County Sheriff's Office evidence managment sytem WolfCom. I would also like to note that the utility line belongs to the Frontier Company. Frontier was contact at 16:45 and stated someone would be on scene within the hour. At 18:25 I had dispatch call back to Frontier who stated they are unable to advise when someone would be responding. I then had dispatch contact Duke Energy to respond. Duke was able to hang the line back up. The Duke lineman advised me he is not sure how far off the roadway the line was previously, however he measured and it is over 15 foot off roadway when he hung it back up. Deputy Ryan UtterFulton County Sheriff's Office
A17: 904167434 | B17: FULTON | C17: ROCHESTER | D17: ROCHESTER | E17: 44881 | F17: 0.97638889 | G17: 2 | I17: 0 | J17: 0 | K17: 0 | M17: E STATE RD 14 | R17: E STATE RD 14 | S17: OAKHILL DR | W17: N | Y17: 0 | AA17: 41.055532 | AB17: -86.158286 | AC17: STATE ROAD | AE17: RURAL | AF17: N | AG17: N | AH17: N | AJ17: DARK (NOT LIGHTED) | AK17: SNOW | AL17: ICE | AN17: NO JUNCTION INVOLVED | AP17: ASPHALT | AQ17: ROADWAY SURFACE CONDITION | AR17: $1001 TO $2500 | AS17: SAME DIRECTION SIDESWIPE | AT17: Y | AU17: N | AV17: OAKHILLDRESTATERD14 | AW17: 0 | AY17: On Wednesday, November 16, 2022 at 23:26, Miller, Abbi responded to a crash on E State Rd 14 at intersection of Oakhill Dr. At the time of the crash, the weather was Snow and the road surface was Ice.Vehicle 1, White Kia Sportage, Maintaining path of travel. Vehicle 2, White Gmc Sierra, Maintaining path of travel. V1 was traveling east on SR 14 when the vehicle hit ice and started to loose control. D1 was attempting to gain control of the vehicle. V2 was slowing down due to V1 loosing control of the vehicle. V1 sideswipped V2 on the passenger side of the vehicle. There was minor damage to both vehicles.
A18: 904167440 | B18: FULTON | C18: ROCHESTER | D18: ATHENS | E18: 44894 | F18: 0.77083333 | G18: 1 | I18: 0 | J18: 0 | K18: 1 | M18: E STATE RD 14 | R18: E STATE RD 14 | S18: S 500 E | W18: N | Y18: 0 | AA18: 41.054375 | AB18: -86.149717 | AC18: STATE ROAD | AE18: RURAL | AF18: N | AG18: N | AH18: N | AJ18: DARK (NOT LIGHTED) | AK18: CLEAR | AL18: DRY | AN18: NO JUNCTION INVOLVED | AP18: ASPHALT | AQ18: ANIMAL/OBJECT IN ROADWAY | AR18: $2501 TO $5000 | AS18: COLLISION WITH DEER | AT18: Y | AU18: Y | AV18: S500EESTATERD14 | AW18: 0 | AY18: On Tuesday, November 29, 2022 at 18:30, Haney, Ryan responded to a crash on E State Rd 14 at intersection of S 500 E. At the time of the crash, the weather was Clear and the road surface was Dry.V1 was traveling west on SR 14 near the intersection of 500 E when a deer entered the roadway. V1 was unable to avoid the deer and struck it. V1 sustained damage to the front passenger side headlight, door, and surrounding panels. D1 continued to work after the accident, the diagram attached is what the driver described.
A19: 904188370 | B19: FULTON | C19: HENRY | D19: AKRON | E19: 44915 | F19: 0.85069444 | G19: 2 | I19: 0 | J19: 0 | K19: 0 | M19: STATE RD 14 | R19: STATE RD 14 | S19: CR 925 E | W19: N | Y19: 0 | AA19: 41.038323 | AB19: -86.071496 | AC19: STATE ROAD | AE19: RURAL | AF19: N | AG19: N | AH19: N | AJ19: DARK (NOT LIGHTED) | AK19: CLEAR | AL19: DRY | AN19: NO JUNCTION INVOLVED | AP19: ASPHALT | AQ19: IMPROPER PASSING | AR19: UNDER $1001 | AS19: OPPOSITE DIRECTION SIDESWIPE | AT19: N | AU19: Y | AV19: STATERD14CR925E | AW19: 0 | AY19: On Tuesday, December 20, 2022 Deputy Mitchell Scott responded to a crash on State Rd 14 at intersection of CR 925 E. At the time of the crash, the weather was Clear and the road surface was Dry.Vehicle 1 was traveling east on State Road 14 at CR 925 E. Driver 1 stated there was a passenger car traveling west on State Road 14 approaching CR 925 E. Driver 1 stated there was a dark in color passenger car traveling west following the vehicle in front closely. Driver 1 stated the second vehicle that was following too closely attempted to pass the vehicle and struck the mirror on vehicle 1 causing the mirror to fall off. Vehicle 1 sustained damage to the mirror only. No other damage to vehicle 1. Driver 1 was unsure of vehicle make, model, or exact color of suspect vehicle. We were unable to locate suspect vehicle.
A20: 904195376 | B20: FULTON | C20: HENRY | D20: AKRON | E20: 44916 | F20: 0.29930556 | G20: 1 | I20: 0 | J20: 0 | K20: 0 | L20: 431 S | M20: 800 E | R20: 800 E | W20: N | Y20: 0 | AA20: 41.047522 | AB20: -86.095191 | AC20: PRIVATE DRIVE | AE20: RURAL | AF20: N | AG20: N | AH20: N | AJ20: DARK (NOT LIGHTED) | AK20: CLEAR | AL20: DRY | AN20: NO JUNCTION INVOLVED | AP20: GRAVEL | AQ20: OTHER (DRIVER) - EXPLAIN IN NARRATIVE | AR20: $2501 TO $5000 | AS20: RAN OFF ROAD | AT20: Y | AU20: N | AV20: 800E | AW20: 0 | AY20: On Wednesday, December 21, 2022 at 07:11, Miller, Abbi responded to a crash on 431 S 800 E . At the time of the crash, the weather was Clear and the road surface was Dry.Vehicle 1, Maroon\Burgundy (purple) Gmc Sierra, Maintaining path of travel. I was dispatched to 431 S 800 E for a report of a truck that struck a post. I arrived on scene and spoke to D1 who advised he was having transmission issues. D1 struck the metal post but did not cause damage to the post but the truck sustained front end damage. While speaking with D1 he admitted that he had been drinking that night. Standardized Field Sobreity Tests were conducted and D1 was taken into custody.
A21: 904206526 | B21: FULTON | C21: HENRY | D21: AKRON | E21: 44941 | F21: 0.33680556 | G21: 1 | I21: 0 | J21: 0 | K21: 1 | M21: STATE RD 14 | R21: STATE RD 14 | W21: N | Y21: 0 | AA21: 41.038991 | AB21: -86.03713 | AC21: STATE ROAD | AE21: RURAL | AF21: N | AG21: N | AH21: N | AJ21: DAWN/DUSK | AK21: CLOUDY | AL21: DRY | AN21: NO JUNCTION INVOLVED | AP21: ASPHALT | AQ21: ANIMAL/OBJECT IN ROADWAY | AR21: $2501 TO $5000 | AS21: COLLISION WITH DEER | AT21: Y | AU21: N | AV21: STATERD14 | AW21: 0 | AY21: V1 WAS TRAVELING EAST ON SR 14. THE DRIVER STATED A DEER RAN INTO THE ROADWAY AND HE COLLIDED WITH IT. V1 CAME TO REST ON THE SOUTH SIDE OF THE ROAD FACING EAST. I WAS UNABLE TO LOCATE THE DEER.
A22: 904209741 | B22: FULTON | C22: HENRY | D22: AKRON | E22: 44946 | F22: 0.44444444 | G22: 2 | I22: 0 | J22: 0 | K22: 0 | M22: STATE RD 14 | R22: STATE RD 14 | S22: S 900 E | W22: N | Y22: 158 | AA22: 41.038934 | AB22: -86.07591 | AC22: STATE ROAD | AE22: RURAL | AF22: N | AG22: N | AH22: N | AJ22: DAYLIGHT | AK22: SNOW | AL22: WET | AN22: T-INTERSECTION | AP22: ASPHALT | AQ22: FOLLOWING TOO CLOSELY | AR22: $5001 TO $10000 | AS22: REAR END | AT22: Y | AU22: Y | AV22: STATERD14S900E | AW22: 0 | AY22: V1 and V2 were both westbound on state road 14 near county road 900 E. D2 started slowing down because of a vehicle in front of him slowing to make the turn onto county road 900 E. D1 was behind V2 and stated that he was reaching for a water bottle and did not notice that V2 was slowing down. V1 ran into the back end of V2. V1 had damage to the front end and it was not drivable, V2 had minor damage to the rear bumper and was able to drive from the scene.
A23: 904213223 | B23: FULTON | C23: HENRY | D23: ATHENS | E23: 44949 | F23: 0.3125 | G23: 1 | I23: 0 | J23: 0 | K23: 0 | M23: STATE RD 14 | R23: STATE RD 14 | S23: S 775 E | W23: N | Y23: 0 | AA23: 41.047424 | AB23: -86.102909 | AC23: STATE ROAD | AE23: RURAL | AF23: N | AG23: N | AH23: N | AJ23: DAWN/DUSK | AK23: SNOW | AL23: ICE | AN23: NO JUNCTION INVOLVED | AP23: ASPHALT | AQ23: SPEED TOO FAST FOR WEATHER CONDITIONS | AR23: $5001 TO $10000 | AS23: RAN OFF ROAD | AT23: Y | AU23: Y | AV23: STATERD14S775E | AW23: 0 | AY23: V1 WAS TRAVELING EAST ON SR 14. THE DRIVER STATED THAT HE TRIED TO PASS A VEHICLE IN FRONT OF HIM BUT LOST CONTROL DUE TO THE ICY ROAD. V1 THEN LEFT THE ROADWAY AND DOWN A SMALL EMBANKMENT. V1 THEN ROLLED OVER ONTO THE PASSENGER SIDE AND CAME TO REST FACING SOUTH.
A24: 904211422 | B24: FULTON | C24: HENRY | D24: AKRON | E24: 44949 | F24: 0.33333333 | G24: 1 | I24: 0 | J24: 0 | K24: 0 | M24: STATE RD 14 | R24: STATE RD 14 | S24: S 1075 E | W24: N | Y24: 0 | AA24: 41.038703 | AB24: -86.04265 | AC24: STATE ROAD | AE24: URBAN | AF24: N | AG24: N | AH24: N | AJ24: DAYLIGHT | AK24: CLOUDY | AL24: ICE | AN24: FOUR-WAY INTERSECTION | AP24: ASPHALT | AQ24: SPEED TOO FAST FOR WEATHER CONDITIONS | AR24: $2501 TO $5000 | AS24: RAN OFF ROAD | AT24: Y | AU24: Y | AV24: STATERD14S1075E | AW24: 0 | AY24: On Monday, January 23, 2023 at 08:00, Jolley, Larry responded to a crash on SR 14 at 1075 E. At the time of the crash, the weather was Cloudy and the road surface was Ice.Vehicle 1, Gray Chrysler Lhs, Run off road right. D1 advised he was traveling east on SR 14 when the vehicle began to slide. D1 advised he left the roadway and collided with a cement culvert. v1 came to rest off of the roadway facing NW.{Conclusion} Cause of crash- Speed to fast for the road conditions.
A25: 904221599 | B25: FULTON | C25: ROCHESTER | D25: ROCHESTER | E25: 44960 | F25: 0.81736111 | G25: 1 | I25: 0 | J25: 0 | K25: 1 | M25: SR 14 | R25: SR 14 | S25: 400 E | W25: N | Y25: 0 | AA25: 41.056373 | AB25: -86.161949 | AE25: RURAL | AF25: N | AG25: N | AH25: N | AJ25: DARK (NOT LIGHTED) | AK25: CLEAR | AL25: DRY | AN25: NO JUNCTION INVOLVED | AP25: ASPHALT | AQ25: ANIMAL/OBJECT IN ROADWAY | AR25: $10001 TO $25000 | AS25: COLLISION WITH DEER | AT25: Y | AU25: N | AV25: SR14400E | AW25: 0 | AY25: V1 was heading eastbound on State Road 114 when a deer was going northbound and collided with V1.
A26: 904228947 | B26: FULTON | C26: ROCHESTER | D26: ROCHESTER | E26: 44974 | F26: 0.33194444 | G26: 2 | I26: 0 | J26: 0 | K26: 0 | M26: BESSMORE PARK ROAD | R26: BESSMORE PARK ROAD | S26: STATE ROAD 14 | W26: Y | Y26: 0 | AA26: 41.057904 | AB26: -86.168724 | AC26: LOCAL/CITY ROAD | AE26: URBAN | AF26: N | AG26: N | AH26: N | AJ26: DAYLIGHT | AK26: CLEAR | AL26: DRY | AN26: FOUR-WAY INTERSECTION | AP26: ASPHALT | AQ26: UNSAFE BACKING | AR26: $2501 TO $5000 | AS26: BACKING CRASH | AT26: Y | AU26: N | AV26: STATEROAD14BESSMOREPARKROAD | AW26: 0 | AY26: On Friday, February 17, 2023 at 07:58, Haines, Ed responded to a crash on Bessmore Park Road at intersection the of State Road 14 and the road surface was Dry.Vehicle 1, Black Ford Ranger, Backing. Vehicle 2, Black Ford Fusion, Slowing or stopped in traffic. D1 stated that he was at the stop sign at SR 14 and Bessmore Park Road. He stated that he felt like he was too close to the intersection and started to back up his vehicle and did not see V2 behind him due to the frost that morning and the glare from the morning sun. V1 backed in to V2D2 stated that she was waiting stopped behind V1 and that V1 backed in to her vehicle for no apparent reason. Both vehicles were at the intersection of State Road 14 and Bessmore Park Road northbound waiting to turn westbound on State Road 14 prior to the collision.
A27: 904234750 | B27: FULTON | C27: HENRY | D27: AKRON | E27: 44985 | F27: 0.88055556 | G27: 1 | I27: 1 | J27: 0 | K27: 0 | O27: 14 | R27: 14 | U27: 800 | W27: N | Y27: 200 | AA27: 41.046884 | AB27: -86.095221 | AC27: STATE ROAD | AE27: RURAL | AF27: N | AG27: N | AH27: N | AJ27: DARK (NOT LIGHTED) | AK27: CLEAR | AL27: DRY | AN27: NO JUNCTION INVOLVED | AP27: ASPHALT | AQ27: DRIVER ILLNESS | AR27: $10001 TO $25000 | AS27: RAN OFF ROAD | AT27: Y | AU27: Y | AV27: 14 | AW27: 0 | AY27: On February 28th, 2023, I responded to a single vehicle crash near State Road 14 and County Road 800 East. When I arrived, I observed a vehicle that had struck a tree and suffered heavy damage. The tree belongs to 583 South County Road 800 East. Driver 1 stated she had potassium issues prior this same day, and does not remember going off the roadway or crashing. Driver 1 was transported by EMS to a trauma center. Driver 1's brother arrived on scene and provided me with Vehicle 1's insurance information. Vehicle 1 went off the roadway a few hundred yards east of County Road 800 East when it was traveling Eastbound on State Road 14. I observed Vehicle 1's tire marks where it left the roadway and drove through the field. Vehicle 1 then crossed County Road 800 East, went through a wire fence, and struck a tree. I would like to note that there were no tire marks on the road, nor were there any skid marks leading up to the tree. Deputy Ryan UtterFulton County Sheriff's Office
A28: 904234777 | B28: FULTON | C28: HENRY | D28: AKRON | E28: 44988 | F28: 0.72986111 | G28: 1 | I28: 0 | J28: 0 | K28: 0 | L28: 9130 | M28: EAST STATE ROAD 14 | R28: EAST STATE ROAD 14 | W28: N | Y28: 0 | AA28: 41.038586 | AB28: -86.074113 | AC28: STATE ROAD | AE28: RURAL | AF28: N | AG28: N | AH28: N | AJ28: DAYLIGHT | AK28: SLEET/HAIL/FREEZING RAIN | AL28: SNOW/SLUSH | AN28: NO JUNCTION INVOLVED | AP28: ASPHALT | AQ28: SPEED TOO FAST FOR WEATHER CONDITIONS | AR28: $2501 TO $5000 | AS28: RAN OFF ROAD | AT28: Y | AU28: Y | AV28: EASTSTATEROAD14 | AW28: 0 | AY28: On March 3rd, 2023 I responded to a single vehicle crash at 9130 East State Road 14. Driver 1 stated he was driving East on State Road 14 when he lost control of his vehicle. Vehicle 1 then left the roadway, and struck a mailbox belonging to 9130 East State Road 14. Vehicle 1 was close to a brick landscaping Colum, however it did not appear Vehicle 1 struck it. I provided owners of the damaged mailbox with this crash number. Tony's City Wide Towing responded to the scene to remove Vehicle 1 off of the mailbox. Vehicle 1 was drivable and not towed away from the scene. Deputy Ryan UtterFulton County Sheriff's Office
A29: 904285597 | B29: FULTON | C29: HENRY | D29: ROCHESTER | E29: 45072 | F29: 0.94027778 | G29: 2 | I29: 1 | J29: 0 | K29: 0 | O29: 14 | R29: 14 | U29: 800 | W29: N | Y29: 1500 | AA29: 41.044484 | AB29: -86.091035 | AC29: STATE ROAD | AE29: RURAL | AF29: N | AG29: N | AH29: N | AJ29: DARK (NOT LIGHTED) | AK29: CLEAR | AL29: DRY | AN29: NO JUNCTION INVOLVED | AP29: ASPHALT | AQ29: OTHER (DRIVER) - EXPLAIN IN NARRATIVE | AR29: $2501 TO $5000 | AS29: SAME DIRECTION SIDESWIPE | AT29: N | AU29: Y | AV29: 14 | AW29: 0 | AY29: On May 26th, 2023, emergency personnel responded to a crash on State Road 14 just east of County Road 800 east. When I arrived on scene I observed a female laying in the roadway with injuries. This female was airlifted by Samaritan due to her injuries. On May 31st, 2023, I spoke to the female passenger who stated she does not remember the crash and couldn't not remember if Vehicle 1 was struck or not. Female passenger also stated she received two stiches in her head, a broken ankle, and road rash as a result of this crash.While on scene, Driver 1 stated he and his friends were traveling East on State Road 14 after coming around a curve in the roadway when he attempted to pass a white in color SUV. I would like to note that this is a "no passing zone" with a solid yellow Eastbound line as well as no passing signs. Driver 1 stated as he passed the SUV and returned to his lane, he observed his rear passenger had "fallen off" his motorcycle. There were multiple other people on scene when I arrived and they are listed in this report as "other participants". All of the other participants stated they did not observe what happened and that there were more people on motorcycles riding with them, however they did not stop. I would like to note that Mr. Scott stated he was not traveling directly with with motorcycle group and that he arrived on scene shortly after the crash happened. Vehicle 1's rear right saddle bag was broke off of the motorcycle. I would like to note that this saddle bag was fiberglass, and pieces were located throughout the scene. Driver 1 stated he had recently purchased Vehicle 1 and did not have insurance on Vehicle 1 or Vehicle 1 registered to him. The Indiana registration plate on Vehicle 1 returned to the previous owner. After standardized field sobriety test, Driver 1 was arrested for operating a motor vehicle while intoxicated with a prior conviction. Driver 1 was also issued a complaint and summons for passing in a no passing zone, and for operating without finical responsibility. Driver 1 had fresh injuries on the rear of his right leg and was checked on by medical staff prior to being lodged at the Fulton County Jail. Later this evening I spoke to Driver 1 who stated he was struck by another motorcycle rider, however he did not know who the other driver was, or what type of motorcycle they were on. This crash report will be considered a "hit and run" due to the new statements made by Driver 1. At this time, I have no suspects or vehicle description other than a motorcycle. The vehicle that reportedly left the scene is listed as Vehicle 2. A criminal case will be completed. I would also like to note that the diagram for this crash is how I observed the scene when I arrived (excluding emergency responders/vehicles).Deputy Ryan UtterFulton County Sheriff's Office
A30: 904285593 | B30: FULTON | C30: HENRY | D30: AKRON | E30: 45073 | F30: 0.49930556 | G30: 2 | I30: 0 | J30: 0 | K30: 0 | L30: 201W | M30: ROCHESTER ST | R30: ROCHESTER ST | W30: Y | Y30: 0 | AA30: 41.038821 | AB30: -86.029583 | AC30: PRIVATE DRIVE | AE30: URBAN | AF30: N | AG30: N | AH30: N | AJ30: DAYLIGHT | AK30: CLEAR | AL30: DRY | AN30: NO JUNCTION INVOLVED | AP30: CONCRETE | AQ30: OTHER (DRIVER) - EXPLAIN IN NARRATIVE | AR30: $2501 TO $5000 | AS30: OPPOSITE DIRECTION SIDESWIPE | AT30: Y | AU30: Y | AV30: ROCHESTERST | AW30: 0 | AY30: D1 was just starting to pull away from a gas pump when she stated that another vehicle was pulling in and she believed it was going to hit her vehicle so she made a sudden move to the right and side swiped the trailer that was next to her at a different gas pump. V2 was parked getting gas, there was no damage to the trailer but V1 had damage down the passenger side.
A31: 904285455 | B31: FULTON | C31: ROCHESTER | D31: ROCHESTER | E31: 45078 | F31: 0.23263889 | G31: 1 | I31: 0 | J31: 0 | K31: 1 | O31: 14 | R31: 14 | U31: 550 | W31: N | Y31: 682 | AA31: 41.05427 | AB31: -86.137495 | AC31: STATE ROAD | AE31: RURAL | AF31: N | AG31: N | AH31: N | AJ31: DARK (NOT LIGHTED) | AK31: CLOUDY | AL31: DRY | AN31: NO JUNCTION INVOLVED | AP31: ASPHALT | AQ31: ANIMAL/OBJECT IN ROADWAY | AR31: $5001 TO $10000 | AS31: COLLISION WITH DEER | AT31: Y | AU31: N | AV31: 14 | AW31: 0 | AY31: D1 was eastbound on state road 14 near county road 550 E when a deer entered the roadway. D1 was unable to avoid striking the deer.
A32: 904296703 | B32: FULTON | C32: ROCHESTER | D32: ROCHESTER | E32: 45088 | F32: 0.17013889 | G32: 1 | I32: 0 | J32: 0 | K32: 1 | M32: SR 14 | R32: SR 14 | S32: 575 E | W32: N | Y32: 0 | AA32: 41.054194 | AB32: -86.134965 | AC32: STATE ROAD | AE32: RURAL | AF32: N | AG32: N | AH32: N | AJ32: DARK (NOT LIGHTED) | AK32: CLEAR | AL32: DRY | AN32: NO JUNCTION INVOLVED | AP32: ASPHALT | AQ32: ANIMAL/OBJECT IN ROADWAY | AR32: $2501 TO $5000 | AS32: COLLISION WITH DEER | AT32: N | AU32: Y | AV32: SR14575E | AW32: 0 | AY32: On Sunday, June 11, 2023 at 04:05, Haney, Ryan responded to a crash on SR 14 at intersection the of 575 E and the road surface was Dry.V1 was traveling east on SR 14 near 575 E when a deer entered the roadway. V1 was unable to avoid the deer and struck it. V1 sustained damage to the entire front end of the vehicle and windshield.
A33: 904296714 | B33: FULTON | C33: HENRY | D33: ROCHESTER | E33: 45096 | F33: 0.46041667 | G33: 1 | I33: 0 | J33: 0 | K33: 0 | M33: STATE ROAD 14 | R33: STATE ROAD 14 | S33: CR 800 E | W33: N | Y33: 0 | AA33: 41.047451 | AB33: -86.094813 | AC33: STATE ROAD | AE33: RURAL | AF33: N | AG33: N | AH33: N | AJ33: DAYLIGHT | AK33: CLEAR | AL33: DRY | AN33: NO JUNCTION INVOLVED | AP33: ASPHALT | AQ33: OVERCORRECTING/OVERSTEERING | AR33: $2501 TO $5000 | AS33: RAN OFF ROAD | AT33: Y | AU33: Y | AV33: STATEROAD14CR800E | AW33: 0 | AY33: On Monday, June 19, 2023 Deputy Mitchell Scott responded to a crash on State Road 14 at intersection the of CR 800 E. Vehicle 1 was traveling west on State Road 14 approaching CR 800 E in the curve. Driver 1 stated his vehicle drives to the right and he had gone off into the gravel on the north side of the roadway. Driver 1 stated he overcorrected and lost control of his vehicle. Driver 1 stated he came back onto the roadway and then off the roadway rolling the vehicle approximately 2 or 3 times according to driver 1. Driver 1 refused on scene medical attention. Witness 1 was sitting at the intersection of CR 800 E and State Road 14. Witness 1 stated vehicle 1 was traveling west on State Road 14 approaching CR 800 E. Witness 1 stated vehicle 1 traveled off the north side of the roadway, overcorrected, and then ran off the north side of the roadway rolling the vehicle. Tony's Citywide Towing took possession of the vehicle.
A34: 904299524 | B34: FULTON | C34: HENRY | D34: AKRON | E34: 45101 | F34: 0.85694444 | G34: 2 | I34: 0 | J34: 0 | K34: 0 | L34: 401 W | M34: ROCHESTER ST | R34: ROCHESTER ST | W34: Y | Y34: 0 | AA34: 41.039047 | AB34: -86.028816 | AE34: URBAN | AF34: N | AG34: N | AH34: N | AJ34: DAWN/DUSK | AK34: CLEAR | AL34: DRY | AN34: NO JUNCTION INVOLVED | AP34: ASPHALT | AQ34: UNSAFE BACKING | AR34: $5001 TO $10000 | AS34: BACKING CRASH | AT34: Y | AU34: Y | AV34: ROCHESTERST | AW34: 0 | AY34: V1 was backing out of the parking space when V1 sideswiped V2. V1 sustained damage ware and V2 sustained damage ware.
A35: 904320174 | B35: FULTON | C35: HENRY | D35: AKRON | E35: 45127 | F35: 0.49305556 | G35: 2 | H35: 0 | I35: 0 | J35: 0 | K35: 0 | O35: SR14E | R35: SR14E | T35: SR19N | W35: Y | Y35: 60 | Z35: E | AA35: 41.038804 | AB35: -86.02801 | AC35: STATE ROAD | AE35: URBAN | AF35: N | AG35: N | AH35: N | AJ35: DAYLIGHT | AK35: CLEAR | AL35: DRY | AN35: NO JUNCTION INVOLVED | AO35: STRAIGHT/GRADE | AP35: ASPHALT | AQ35: IMPROPER TURNING | AR35: $2501 TO $5000 | AS35: SAME DIRECTION SIDESWIPE | AT35: Y | AU35: Y | AV35: SR14ESR19N | AW35: 0 | AX35: NONE | AY35: DRIVER 1 WAS TURNING FROM S.R. 19 NORT ONTO S.R. 14 EAST AND STRUCK UNIT 2 CAUSING DAMAGE TO THE DRIVER SIDE FENDER OF UNIT 2 AND DAMAGE TO THE PASSENGER SIDE FENDER OF UNIT 1 . DRIVER 1 LEFT THE SCENE OF THE ACCIDENT BUT DID COME TO THE AKRON POLICE DEPARTMENT A SHORT TIME LATER AND ADMIT TO THE ACCIDENT .
A36: 904314708 | B36: FULTON | C36: ROCHESTER | D36: ROCHESTER | E36: 45128 | F36: 0.35277778 | G36: 2 | I36: 0 | J36: 0 | K36: 0 | O36: 14 | R36: 14 | U36: 500 | W36: N | Y36: 1456 | AA36: 41.05456 | AB36: -86.155308 | AC36: STATE ROAD | AE36: RURAL | AF36: N | AG36: N | AH36: N | AJ36: DAYLIGHT | AK36: CLEAR | AL36: DRY | AN36: NO JUNCTION INVOLVED | AP36: ASPHALT | AQ36: FOLLOWING TOO CLOSELY | AR36: $5001 TO $10000 | AS36: REAR END | AT36: Y | AU36: Y | AV36: 14 | AW36: 0 | AY36: V1 and V2 were both westbound on state road 14 near county road 500 E. V1 was following V2, D1 stated that she ran into the rear of V2. D1 was not sure what exactly happened other than she ran into the rear of V2.
A37: 904363515 | B37: FULTON | C37: ROCHESTER | D37: ROCHESTER | E37: 45197 | F37: 0.24652778 | G37: 1 | I37: 0 | J37: 0 | K37: 0 | M37: SR 14 | R37: SR 14 | S37: BESSMORE PARK RD | W37: N | Y37: 0 | AA37: 41.056756 | AB37: -86.163826 | AC37: STATE ROAD | AE37: RURAL | AF37: N | AG37: N | AH37: N | AJ37: DARK (NOT LIGHTED) | AK37: CLOUDY | AL37: DRY | AN37: NO JUNCTION INVOLVED | AP37: ASPHALT | AQ37: ANIMAL/OBJECT IN ROADWAY | AR37: $2501 TO $5000 | AS37: COLLISION WITH DEER | AT37: Y | AU37: N | AV37: SR14BESSMOREPARKRD | AW37: 0 | AY37: V1 WAS TRAVELING EAST ON SR 14. THE DRIVER STATED SEVERAL DEER RAN INTO THE ROAD AND SHE COLLIDED WITH ONE. V1 CAME TO REST ON THE SOUTH SIDE OF THE ROAD FACING EAST
A38: 904372464 | B38: FULTON | C38: HENRY | D38: ATHENS | E38: 45203 | F38: 0.86458333 | G38: 1 | I38: 0 | J38: 0 | K38: 1 | M38: SR 14 | R38: SR 14 | S38: 775 E | W38: N | Y38: 0 | AA38: 41.047444 | AB38: -86.102297 | AC38: STATE ROAD | AE38: RURAL | AF38: N | AG38: N | AH38: N | AJ38: DARK (NOT LIGHTED) | AK38: CLOUDY | AL38: DRY | AN38: NO JUNCTION INVOLVED | AP38: ASPHALT | AQ38: ANIMAL/OBJECT IN ROADWAY | AR38: $2501 TO $5000 | AS38: COLLISION WITH DEER | AT38: Y | AU38: N | AV38: SR14775E | AW38: 0 | AY38: V1 WAS TRAVELING EAST ON SR 14. THE DRIVER STATED A DEER RAN INTO THE ROADWAY AND HE COLLIDED WITH IT. V1 CAME TO REST ON THE SOUTH SIDE OF THE ROAD FACING EAST.
A39: 904390601 | B39: FULTON | C39: HENRY | D39: AKRON | E39: 45240 | F39: 0.27708333 | G39: 1 | I39: 0 | J39: 0 | K39: 1 | O39: 14 | R39: 14 | U39: 100 | W39: N | Y39: 1394 | AA39: 41.039371 | AB39: -86.051936 | AC39: STATE ROAD | AE39: RURAL | AF39: N | AG39: N | AH39: N | AJ39: DARK (NOT LIGHTED) | AK39: CLEAR | AL39: DRY | AN39: NO JUNCTION INVOLVED | AP39: ASPHALT | AQ39: ANIMAL/OBJECT IN ROADWAY | AR39: $5001 TO $10000 | AS39: COLLISION WITH DEER | AT39: Y | AU39: N | AV39: 14 | AW39: 0 | AY39: D1 was eastbound on state road 14 near county road 1000 E when a deer entered the roadway. D1 was unable to avoid striking the deer.
A40: 904409231 | B40: FULTON | C40: HENRY | D40: AKRON | E40: 45261 | F40: 0.66666667 | G40: 2 | I40: 0 | J40: 0 | K40: 0 | M40: STATE ROAD 19 | R40: STATE ROAD 19 | S40: STATE ROAD 14 | W40: Y | Y40: 0 | AA40: 41.039076 | AB40: -86.028338 | AC40: STATE ROAD | AE40: URBAN | AF40: N | AG40: N | AH40: N | AJ40: DAYLIGHT | AK40: CLEAR | AL40: DRY | AN40: FOUR-WAY INTERSECTION | AP40: ASPHALT | AQ40: OTHER (ENVIRONMENTAL) - EXPLAIN IN NARR | AR40: $1001 TO $2500 | AS40: SAME DIRECTION SIDESWIPE | AT40: Y | AU40: Y | AV40: STATEROAD19STATEROAD14 | AW40: 0 | AY40: On December 2, 2023 I was dispatched to 104 N Mishawaka Street, Akron, Indiana for a crash report. I arrived and spoke to Ashley Prater who advised sometime the day before, December 1, between the hours of 4 and 5 p.m., her vehicle had been struck by a vehicle that had fled the scene. I observed her vehicle and it had fresh front driver's side damage to the quarter panel that was consistent with a same direction side swipe. Ms. Prater did not have any information about a suspect vehicle and the surveillance videos in the area did not capture the area in question. There are currently no further leads to pursue in regards to locating Vehicle 1, which fled the scene. Information was taken from Ms. Prater for this report to be filed.
...

Sheet Target Individual Records
